Workbook

Sheet Guide d'utilisation
A1: Guide d'utilisation
A4: Pour tous les onglets : toutes les cellules grisées sont des cellules qui se remplissent automatiquement
A6: Etape 1 : remplir les données de l'onglet Data_metier
B7: - Pour les niveaux des ressources transversales (colonne C à E), vous devez utiliser cette syntaxe :
C8: Niveau 1
C9: Niveau 2
C10: Niveau 3
C11: Niveau 4
B13: -Pour la colonne responsabilité transversale (colonne F), vous devez utiliser cette syntaxe :
C14: Significatif
C15: Non significatif
B17: - Pour la colonne Interface (colonne G), vous devez utiliser cette syntaxe :
C18: Oui, en amont OU aval
C19: Oui, en amont ET aval
C20: Non
A22: Etape 2 : S'il y a de nouveaux formacodeq non présents dans la base, les intégrer dans l'onglet "Formacode"
B23: Les cellules oranges foncées sont les niveaux de DC pour lesquels il n'y a pas de nombre d'heures associées
A25: Etape 3 : Remplir les formacodes que vous utilisez dans la colonne B
B26: Le nom des DC (colonne A) apparaitront automatiquement selon les libellés de l'onglet "Formacode"
A29: Etape 4 : Choisir le métier de départ dans la cellule B4 dans l'onglet "Métiers passerelles"

Sheet Data_metier
A1: DOSSIER_SOURCE | B1: INT_METIER | C1: TRANSV_2 | D1: TRANSV_8 | E1: TRANSV_10 | F1: RESPONS_TRANS | G1: INTERFACE | H1: NIVEAU_FORMATION
A2: OCAPIAT_cartographie metiers production alimentaire | B2: Caviste | C2: Niveau 1 | D2: Niveau 1 | E2: Niveau 1 | F2: Non significatif | G2: Oui, en amont OU aval | H2: 4
A3: OCAPIAT_cartographie metiers production alimentaire | B3: Agent de silo | C3: Niveau 2 | D3: Niveau 1 | E3: Niveau 2 | F3: Non significatif | G3: Non | H3: 4
A4: INTERGROS_cartographie metiers commerce gros | B4: Opérateur(trice) logistique | C4: Niveau 1 | D4: Niveau 1 | E4: Niveau 1 | F4: Non significatif | G4: Non | H4: 3
A5: INTERGROS_cartographie metiers commerce gros | B5: Manager(euse) logistique | C5: Niveau 3 | D5: Niveau 3 | E5: Niveau 3 | F5: Significatif | G5: Oui, en amont ET aval | H5: 5.5
A6: OCAPIAT_cartographie metiers production alimentaire | B6: Maître(sse) de chai | C6: Niveau 2 | D6: Niveau 3 | E6: Niveau 3 | F6: Non significatif | G6: Oui, en amont ET aval | H6: 6
A7: OCAPIAT_cartographie metiers production alimentaire | B7: Superviseur(se) de production (fabrication / conditionnement) | C7: Niveau 3 | D7: Niveau 3 | E7: Niveau 3 | F7: Significatif | G7: Oui, en amont OU aval | H7: 6
A8: OCAPIAT_cartographie metiers production alimentaire | B8: Spécialiste planning / ordonnancement | C8: Niveau 3 | D8: Niveau 3 | E8: Niveau 3 | F8: Significatif | G8: Oui, en amont ET aval | H8: 6
A9: OCAPIAT_cartographie metiers production alimentaire | B9: Opérateur(trice) logistique | C9: Niveau 1 | D9: Niveau 1 | E9: Niveau 1 | F9: Non significatif | G9: Non | H9: 3
A10: OCAPIAT_cartographie metiers production alimentaire | B10: Logisticien(ne) approvisionneur(se) | C10: Niveau 2 | D10: Niveau 2 | E10: Niveau 3 | F10: Non significatif | G10: Oui, en amont OU aval | H10: 5.5
A11: OCAPIAT_cartographie metiers production alimentaire | B11: Responsable de production de produits alimentaires (fabrication / conditionnement) | C11: Niveau 4 | D11: Niveau 4 | E11: Niveau 4 | F11: Significatif | G11: Oui, en amont ET aval | H11: 7
A12: INTERGROS_cartographie metiers commerce gros | B12: Chauffeur(se) livreur(se) | C12: Niveau 2 | D12: Niveau 2 | E12: Niveau 2 | F12: Non significatif | G12: Non | H12: 3
A13: OCAPIAT_cartographie metiers production alimentaire | B13: Régleur(se) | C13: Niveau 2 | D13: Niveau 1 | E13: Niveau 1 | F13: Non significatif | G13: Non | H13: 4
... A30: OCAPIAT_cartographie metiers production alimentaire | B30: Electromécanicien(ne) de maintenance industrielle | C30: Niveau 2 | D30: Niveau 1 | E30: Niveau 2 | F30: Non significatif | G30: Oui, en amont OU aval | H30: 4.5

Sheet DE_niv_form
B1: {=TRANSPOSE(Tableau1[INT_METIER])} -> Caviste | C1: Agent de silo | D1: Opérateur(trice) logistique | E1: Manager(euse) logistique | F1: Maître(sse) de chai | G1: Superviseur(se) de production (fabrication / conditionnement) | H1: Spécialiste planning / ordonnancement | I1: Opérateur(trice) logistique | J1: Logisticien(ne) approvisionneur(se) | K1: Responsable de production de produits alimentaires (fabrication / conditionnement) | L1: Chauffeur(se) livreur(se) | M1: Régleur(se) | N1: Spécialiste procédés et installations de production alimentaire | O1: Conducteur(trice) de livraison et de collecte | P1: Opérateur(trice) hygiène / sanitation | Q1: Chef(fe) de silo | R1: Acheteur(se) / négociateur(trice) de matières premières | S1: Opérateur(trice) de production alimentaire | T1: Conducteur(trice) de machine(s) de production alimentaire (fabrication / conditionnement) | U1: Boulanger(ère)/pâtissier(ère) industriel(le) | V1: Conducteur(trice) de ligne(s)de production alimentaire (fabrication/conditionnement) | W1: Conducteur(trice) de process de production alimentaire | X1: Responsable de plateforme/ d’exploitation logistique | Y1: Opérateur(trice) de transformation des viandes | Z1: Fromager(ère) industriel(le) | AA1: Opérateur(trice) de préparation de poissons et de produits de la mer | AB1: Mécanicien(ne) de maintenance industrielle | AC1: Mécanicien(ne)-sertisseur(euse) | AD1: Electromécanicien(ne) de maintenance industrielle
A2: {=Tableau1[INT_METIER]} -> Caviste | B2: =IF(INDEX(Data_metier!$H:$H,MATCH($A2,Data_metier!$B:$B,0))-INDEX(Data_metier!$H:$H,MATCH(B$1,Data_metier!$B:$B,0))< 0,-1, IF(AND(INDEX(Data_metier!$H:$H,MATCH($A2,Data_metier!$B:$B,0))-INDEX(Data_metier!$H:$H,MATCH(B$1,Data_metier!$B:$B,0))> 0, INDEX(Data_metier!$H:$H,MATCH($A2,Data_metier!$B:$B,0))-INDEX(Data_metier!$H:$H,MATCH(B$1,Data_metier!$B:$B,0))<=1), 1, IF(INDEX(Data_metier!$H:$H,MATCH($A2,Data_metier!$B:$B,0))-INDEX(Data_metier!$H:$H,MATCH(B$1,Data_metier!$B:$B,0))> 1, 2, 0))) -> 0 | C2: =IF(INDEX(Data_metier!$H:$H,MATCH($A2,Data_metier!$B:$B,0))-INDEX(Data_metier!$H:$H,MATCH(C$1,Data_metier!$B:$B,0))< 0,-1, IF(AND(INDEX(Data_metier!$H:$H,MATCH($A2,Data_metier!$B:$B,0))-INDEX(Data_metier!$H:$H,MATCH(C$1,Data_metier!$B:$B,0))> 0, INDEX(Data_metier!$H:$H,MATCH($A2,Data_metier!$B:$B,0))-INDEX(Data_metier!$H:$H,MATCH(C$1,Data_metier!$B:$B,0))<=1), 1, IF(INDEX(Data_metier!$H:$H,MATCH($A2,Data_metier!$B:$B,0))-INDEX(Data_metier!$H:$H,MATCH(C$1,Data_metier!$B:$B,0))> 1, 2, 0))) -> 0 | D2: =IF(INDEX(Data_metier!$H:$H,MATCH($A2,Data_metier!$B:$B,0))-INDEX(Data_metier!$H:$H,MATCH(D$1,Data_metier!$B:$B,0))< 0,-1, IF(AND(INDEX(Data_metier!$H:$H,MATCH($A2,Data_metier!$B:$B,0))-INDEX(Data_metier!$H:$H,MATCH(D$1,Data_metier!$B:$B,0))> 0, INDEX(Data_metier!$H:$H,MATCH($A2,Data_metier!$B:$B,0))-INDEX(Data_metier!$H:$H,MATCH(D$1,Data_metier!$B:$B,0))<=1), 1, IF(INDEX(Data_metier!$H:$H,MATCH($A2,Data_metier!$B:$B,0))-INDEX(Data_metier!$H:$H,MATCH(D$1,Data_metier!$B:$B,0))> 1, 2, 0))) -> 1 | E2: =IF(INDEX(Data_metier!$H:$H,MATCH($A2,Data_metier!$B:$B,0))-INDEX(Data_metier!$H:$H,MATCH(E$1,Data_metier!$B:$B,0))< 0,-1, IF(AND(INDEX(Data_metier!$H:$H,MATCH($A2,Data_metier!$B:$B,0))-INDEX(Data_metier!$H:$H,MATCH(E$1,Data_metier!$B:$B,0))> 0, INDEX(Data_metier!$H:$H,MATCH($A2,Data_metier!$B:$B,0))-INDEX(Data_metier!$H:$H,MATCH(E$1,Data_metier!$B:$B,0))<=1), 1, IF(INDEX(Data_metier!$H:$H,MATCH($A2,Data_metier!$B:$B,0))-INDEX(Data_metier!$H:$H,MATCH(E$1,Data_metier!$B:$B,0))> 1, 2, 0))) -> -1 | F2: =IF(INDEX(Data_metier!$H:$H,MATCH($A2,Data_metier!$B:$B,0))-INDEX(Data_metier!$H:$H,MATCH(F$1,Data_metier!$B:$B,0))< 0,-1, IF(AND(INDEX(Data_metier!$H:$H,MATCH($A2,Data_metier!$B:$B,0))-INDEX(Data_metier!$H:$H,MATCH(F$1,Data_metier!$B:$B,0))> 0, INDEX(Data_metier!$H:$H,MATCH($A2,Data_metier!$B:$B,0))-INDEX(Data_metier!$H:$H,MATCH(F$1,Data_metier!$B:$B,0))<=1), 1, IF(INDEX(Data_metier!$H:$H,MATCH($A2,Data_metier!$B:$B,0))-INDEX(Data_metier!$H:$H,MATCH(F$1,Data_metier!$B:$B,0))> 1, 2, 0))) -> -1 | G2: =IF(INDEX(Data_metier!$H:$H,MATCH($A2,Data_metier!$B:$B,0))-INDEX(Data_metier!$H:$H,MATCH(G$1,Data_metier!$B:$B,0))< 0,-1, IF(AND(INDEX(Data_metier!$H:$H,MATCH($A2,Data_metier!$B:$B,0))-INDEX(Data_metier!$H:$H,MATCH(G$1,Data_metier!$B:$B,0))> 0, INDEX(Data_metier!$H:$H,MATCH($A2,Data_metier!$B:$B,0))-INDEX(Data_metier!$H:$H,MATCH(G$1,Data_metier!$B:$B,0))<=1), 1, IF(INDEX(Data_metier!$H:$H,MATCH($A2,Data_metier!$B:$B,0))-INDEX(Data_metier!$H:$H,MATCH(G$1,Data_metier!$B:$B,0))> 1, 2, 0))) -> -1 | H2: =IF(INDEX(Data_metier!$H:$H,MATCH($A2,Data_metier!$B:$B,0))-INDEX(Data_metier!$H:$H,MATCH(H$1,Data_metier!$B:$B,0))< 0,-1, IF(AND(INDEX(Data_metier!$H:$H,MATCH($A2,Data_metier!$B:$B,0))-INDEX(Data_metier!$H:$H,MATCH(H$1,Data_metier!$B:$B,0))> 0, INDEX(Data_metier!$H:$H,MATCH($A2,Data_metier!$B:$B,0))-INDEX(Data_metier!$H:$H,MATCH(H$1,Data_metier!$B:$B,0))<=1), 1, IF(INDEX(Data_metier!$H:$H,MATCH($A2,Data_metier!$B:$B,0))-INDEX(Data_metier!$H:$H,MATCH(H$1,Data_metier!$B:$B,0))> 1, 2, 0))) -> -1 | I2: =IF(INDEX(Data_metier!$H:$H,MATCH($A2,Data_metier!$B:$B,0))-INDEX(Data_metier!$H:$H,MATCH(I$1,Data_metier!$B:$B,0))< 0,-1, IF(AND(INDEX(Data_metier!$H:$H,MATCH($A2,Data_metier!$B:$B,0))-INDEX(Data_metier!$H:$H,MATCH(I$1,Data_metier!$B:$B,0))> 0, INDEX(Data_metier!$H:$H,MATCH($A2,Data_metier!$B:$B,0))-INDEX(Data_metier!$H:$H,MATCH(I$1,Data_metier!$B:$B,0))<=1), 1, IF(INDEX(Data_metier!$H:$H,MATCH($A2,Data_metier!$B:$B,0))-INDEX(Data_metier!$H:$H,MATCH(I$1,Data_metier!$B:$B,0))> 1, 2, 0))) -> 1 | ... AD2: =IF(INDEX(Data_metier!$H:$H,MATCH($A2,Data_metier!$B:$B,0))-INDEX(Data_metier!$H:$H,MATCH(AD$1,Data_metier!$B:$B,0))< 0,-1, IF(AND(INDEX(Data_metier!$H:$H,MATCH($A2,Data_metier!$B:$B,0))-INDEX(Data_metier!$H:$H,MATCH(AD$1,Data_metier!$B:$B,0))> 0, INDEX(Data_metier!$H:$H,MATCH($A2,Data_metier!$B:$B,0))-INDEX(Data_metier!$H:$H,MATCH(AD$1,Data_metier!$B:$B,0))<=1), 1, IF(INDEX(Data_metier!$H:$H,MATCH($A2,Data_metier!$B:$B,0))-INDEX(Data_metier!$H:$H,MATCH(AD$1,Data_metier!$B:$B,0))> 1, 2, 0))) -> -1
A3: Agent de silo | B3: =IF(INDEX(Data_metier!$H:$H,MATCH($A3,Data_metier!$B:$B,0))-INDEX(Data_metier!$H:$H,MATCH(B$1,Data_metier!$B:$B,0))< 0,-1, IF(AND(INDEX(Data_metier!$H:$H,MATCH($A3,Data_metier!$B:$B,0))-INDEX(Data_metier!$H:$H,MATCH(B$1,Data_metier!$B:$B,0))> 0, INDEX(Data_metier!$H:$H,MATCH($A3,Data_metier!$B:$B,0))-INDEX(Data_metier!$H:$H,MATCH(B$1,Data_metier!$B:$B,0))<=1), 1, IF(INDEX(Data_metier!$H:$H,MATCH($A3,Data_metier!$B:$B,0))-INDEX(Data_metier!$H:$H,MATCH(B$1,Data_metier!$B:$B,0))> 1, 2, 0))) -> 0 | C3: =IF(INDEX(Data_metier!$H:$H,MATCH($A3,Data_metier!$B:$B,0))-INDEX(Data_metier!$H:$H,MATCH(C$1,Data_metier!$B:$B,0))< 0,-1, IF(AND(INDEX(Data_metier!$H:$H,MATCH($A3,Data_metier!$B:$B,0))-INDEX(Data_metier!$H:$H,MATCH(C$1,Data_metier!$B:$B,0))> 0, INDEX(Data_metier!$H:$H,MATCH($A3,Data_metier!$B:$B,0))-INDEX(Data_metier!$H:$H,MATCH(C$1,Data_metier!$B:$B,0))<=1), 1, IF(INDEX(Data_metier!$H:$H,MATCH($A3,Data_metier!$B:$B,0))-INDEX(Data_metier!$H:$H,MATCH(C$1,Data_metier!$B:$B,0))> 1, 2, 0))) -> 0 | D3: =IF(INDEX(Data_metier!$H:$H,MATCH($A3,Data_metier!$B:$B,0))-INDEX(Data_metier!$H:$H,MATCH(D$1,Data_metier!$B:$B,0))< 0,-1, IF(AND(INDEX(Data_metier!$H:$H,MATCH($A3,Data_metier!$B:$B,0))-INDEX(Data_metier!$H:$H,MATCH(D$1,Data_metier!$B:$B,0))> 0, INDEX(Data_metier!$H:$H,MATCH($A3,Data_metier!$B:$B,0))-INDEX(Data_metier!$H:$H,MATCH(D$1,Data_metier!$B:$B,0))<=1), 1, IF(INDEX(Data_metier!$H:$H,MATCH($A3,Data_metier!$B:$B,0))-INDEX(Data_metier!$H:$H,MATCH(D$1,Data_metier!$B:$B,0))> 1, 2, 0))) -> 1 | E3: =IF(INDEX(Data_metier!$H:$H,MATCH($A3,Data_metier!$B:$B,0))-INDEX(Data_metier!$H:$H,MATCH(E$1,Data_metier!$B:$B,0))< 0,-1, IF(AND(INDEX(Data_metier!$H:$H,MATCH($A3,Data_metier!$B:$B,0))-INDEX(Data_metier!$H:$H,MATCH(E$1,Data_metier!$B:$B,0))> 0, INDEX(Data_metier!$H:$H,MATCH($A3,Data_metier!$B:$B,0))-INDEX(Data_metier!$H:$H,MATCH(E$1,Data_metier!$B:$B,0))<=1), 1, IF(INDEX(Data_metier!$H:$H,MATCH($A3,Data_metier!$B:$B,0))-INDEX(Data_metier!$H:$H,MATCH(E$1,Data_metier!$B:$B,0))> 1, 2, 0))) -> -1 | F3: =IF(INDEX(Data_metier!$H:$H,MATCH($A3,Data_metier!$B:$B,0))-INDEX(Data_metier!$H:$H,MATCH(F$1,Data_metier!$B:$B,0))< 0,-1, IF(AND(INDEX(Data_metier!$H:$H,MATCH($A3,Data_metier!$B:$B,0))-INDEX(Data_metier!$H:$H,MATCH(F$1,Data_metier!$B:$B,0))> 0, INDEX(Data_metier!$H:$H,MATCH($A3,Data_metier!$B:$B,0))-INDEX(Data_metier!$H:$H,MATCH(F$1,Data_metier!$B:$B,0))<=1), 1, IF(INDEX(Data_metier!$H:$H,MATCH($A3,Data_metier!$B:$B,0))-INDEX(Data_metier!$H:$H,MATCH(F$1,Data_metier!$B:$B,0))> 1, 2, 0))) -> -1 | G3: =IF(INDEX(Data_metier!$H:$H,MATCH($A3,Data_metier!$B:$B,0))-INDEX(Data_metier!$H:$H,MATCH(G$1,Data_metier!$B:$B,0))< 0,-1, IF(AND(INDEX(Data_metier!$H:$H,MATCH($A3,Data_metier!$B:$B,0))-INDEX(Data_metier!$H:$H,MATCH(G$1,Data_metier!$B:$B,0))> 0, INDEX(Data_metier!$H:$H,MATCH($A3,Data_metier!$B:$B,0))-INDEX(Data_metier!$H:$H,MATCH(G$1,Data_metier!$B:$B,0))<=1), 1, IF(INDEX(Data_metier!$H:$H,MATCH($A3,Data_metier!$B:$B,0))-INDEX(Data_metier!$H:$H,MATCH(G$1,Data_metier!$B:$B,0))> 1, 2, 0))) -> -1 | H3: =IF(INDEX(Data_metier!$H:$H,MATCH($A3,Data_metier!$B:$B,0))-INDEX(Data_metier!$H:$H,MATCH(H$1,Data_metier!$B:$B,0))< 0,-1, IF(AND(INDEX(Data_metier!$H:$H,MATCH($A3,Data_metier!$B:$B,0))-INDEX(Data_metier!$H:$H,MATCH(H$1,Data_metier!$B:$B,0))> 0, INDEX(Data_metier!$H:$H,MATCH($A3,Data_metier!$B:$B,0))-INDEX(Data_metier!$H:$H,MATCH(H$1,Data_metier!$B:$B,0))<=1), 1, IF(INDEX(Data_metier!$H:$H,MATCH($A3,Data_metier!$B:$B,0))-INDEX(Data_metier!$H:$H,MATCH(H$1,Data_metier!$B:$B,0))> 1, 2, 0))) -> -1 | I3: =IF(INDEX(Data_metier!$H:$H,MATCH($A3,Data_metier!$B:$B,0))-INDEX(Data_metier!$H:$H,MATCH(I$1,Data_metier!$B:$B,0))< 0,-1, IF(AND(INDEX(Data_metier!$H:$H,MATCH($A3,Data_metier!$B:$B,0))-INDEX(Data_metier!$H:$H,MATCH(I$1,Data_metier!$B:$B,0))> 0, INDEX(Data_metier!$H:$H,MATCH($A3,Data_metier!$B:$B,0))-INDEX(Data_metier!$H:$H,MATCH(I$1,Data_metier!$B:$B,0))<=1), 1, IF(INDEX(Data_metier!$H:$H,MATCH($A3,Data_metier!$B:$B,0))-INDEX(Data_metier!$H:$H,MATCH(I$1,Data_metier!$B:$B,0))> 1, 2, 0))) -> 1 | ... AD3: =IF(INDEX(Data_metier!$H:$H,MATCH($A3,Data_metier!$B:$B,0))-INDEX(Data_metier!$H:$H,MATCH(AD$1,Data_metier!$B:$B,0))< 0,-1, IF(AND(INDEX(Data_metier!$H:$H,MATCH($A3,Data_metier!$B:$B,0))-INDEX(Data_metier!$H:$H,MATCH(AD$1,Data_metier!$B:$B,0))> 0, INDEX(Data_metier!$H:$H,MATCH($A3,Data_metier!$B:$B,0))-INDEX(Data_metier!$H:$H,MATCH(AD$1,Data_metier!$B:$B,0))<=1), 1, IF(INDEX(Data_metier!$H:$H,MATCH($A3,Data_metier!$B:$B,0))-INDEX(Data_metier!$H:$H,MATCH(AD$1,Data_metier!$B:$B,0))> 1, 2, 0))) -> -1
A4: Opérateur(trice) logistique | B4: =IF(INDEX(Data_metier!$H:$H,MATCH($A4,Data_metier!$B:$B,0))-INDEX(Data_metier!$H:$H,MATCH(B$1,Data_metier!$B:$B,0))< 0,-1, IF(AND(INDEX(Data_metier!$H:$H,MATCH($A4,Data_metier!$B:$B,0))-INDEX(Data_metier!$H:$H,MATCH(B$1,Data_metier!$B:$B,0))> 0, INDEX(Data_metier!$H:$H,MATCH($A4,Data_metier!$B:$B,0))-INDEX(Data_metier!$H:$H,MATCH(B$1,Data_metier!$B:$B,0))<=1), 1, IF(INDEX(Data_metier!$H:$H,MATCH($A4,Data_metier!$B:$B,0))-INDEX(Data_metier!$H:$H,MATCH(B$1,Data_metier!$B:$B,0))> 1, 2, 0))) -> -1 | C4: =IF(INDEX(Data_metier!$H:$H,MATCH($A4,Data_metier!$B:$B,0))-INDEX(Data_metier!$H:$H,MATCH(C$1,Data_metier!$B:$B,0))< 0,-1, IF(AND(INDEX(Data_metier!$H:$H,MATCH($A4,Data_metier!$B:$B,0))-INDEX(Data_metier!$H:$H,MATCH(C$1,Data_metier!$B:$B,0))> 0, INDEX(Data_metier!$H:$H,MATCH($A4,Data_metier!$B:$B,0))-INDEX(Data_metier!$H:$H,MATCH(C$1,Data_metier!$B:$B,0))<=1), 1, IF(INDEX(Data_metier!$H:$H,MATCH($A4,Data_metier!$B:$B,0))-INDEX(Data_metier!$H:$H,MATCH(C$1,Data_metier!$B:$B,0))> 1, 2, 0))) -> -1 | D4: =IF(INDEX(Data_metier!$H:$H,MATCH($A4,Data_metier!$B:$B,0))-INDEX(Data_metier!$H:$H,MATCH(D$1,Data_metier!$B:$B,0))< 0,-1, IF(AND(INDEX(Data_metier!$H:$H,MATCH($A4,Data_metier!$B:$B,0))-INDEX(Data_metier!$H:$H,MATCH(D$1,Data_metier!$B:$B,0))> 0, INDEX(Data_metier!$H:$H,MATCH($A4,Data_metier!$B:$B,0))-INDEX(Data_metier!$H:$H,MATCH(D$1,Data_metier!$B:$B,0))<=1), 1, IF(INDEX(Data_metier!$H:$H,MATCH($A4,Data_metier!$B:$B,0))-INDEX(Data_metier!$H:$H,MATCH(D$1,Data_metier!$B:$B,0))> 1, 2, 0))) -> 0 | E4: =IF(INDEX(Data_metier!$H:$H,MATCH($A4,Data_metier!$B:$B,0))-INDEX(Data_metier!$H:$H,MATCH(E$1,Data_metier!$B:$B,0))< 0,-1, IF(AND(INDEX(Data_metier!$H:$H,MATCH($A4,Data_metier!$B:$B,0))-INDEX(Data_metier!$H:$H,MATCH(E$1,Data_metier!$B:$B,0))> 0, INDEX(Data_metier!$H:$H,MATCH($A4,Data_metier!$B:$B,0))-INDEX(Data_metier!$H:$H,MATCH(E$1,Data_metier!$B:$B,0))<=1), 1, IF(INDEX(Data_metier!$H:$H,MATCH($A4,Data_metier!$B:$B,0))-INDEX(Data_metier!$H:$H,MATCH(E$1,Data_metier!$B:$B,0))> 1, 2, 0))) -> -1 | F4: =IF(INDEX(Data_metier!$H:$H,MATCH($A4,Data_metier!$B:$B,0))-INDEX(Data_metier!$H:$H,MATCH(F$1,Data_metier!$B:$B,0))< 0,-1, IF(AND(INDEX(Data_metier!$H:$H,MATCH($A4,Data_metier!$B:$B,0))-INDEX(Data_metier!$H:$H,MATCH(F$1,Data_metier!$B:$B,0))> 0, INDEX(Data_metier!$H:$H,MATCH($A4,Data_metier!$B:$B,0))-INDEX(Data_metier!$H:$H,MATCH(F$1,Data_metier!$B:$B,0))<=1), 1, IF(INDEX(Data_metier!$H:$H,MATCH($A4,Data_metier!$B:$B,0))-INDEX(Data_metier!$H:$H,MATCH(F$1,Data_metier!$B:$B,0))> 1, 2, 0))) -> -1 | G4: =IF(INDEX(Data_metier!$H:$H,MATCH($A4,Data_metier!$B:$B,0))-INDEX(Data_metier!$H:$H,MATCH(G$1,Data_metier!$B:$B,0))< 0,-1, IF(AND(INDEX(Data_metier!$H:$H,MATCH($A4,Data_metier!$B:$B,0))-INDEX(Data_metier!$H:$H,MATCH(G$1,Data_metier!$B:$B,0))> 0, INDEX(Data_metier!$H:$H,MATCH($A4,Data_metier!$B:$B,0))-INDEX(Data_metier!$H:$H,MATCH(G$1,Data_metier!$B:$B,0))<=1), 1, IF(INDEX(Data_metier!$H:$H,MATCH($A4,Data_metier!$B:$B,0))-INDEX(Data_metier!$H:$H,MATCH(G$1,Data_metier!$B:$B,0))> 1, 2, 0))) -> -1 | H4: =IF(INDEX(Data_metier!$H:$H,MATCH($A4,Data_metier!$B:$B,0))-INDEX(Data_metier!$H:$H,MATCH(H$1,Data_metier!$B:$B,0))< 0,-1, IF(AND(INDEX(Data_metier!$H:$H,MATCH($A4,Data_metier!$B:$B,0))-INDEX(Data_metier!$H:$H,MATCH(H$1,Data_metier!$B:$B,0))> 0, INDEX(Data_metier!$H:$H,MATCH($A4,Data_metier!$B:$B,0))-INDEX(Data_metier!$H:$H,MATCH(H$1,Data_metier!$B:$B,0))<=1), 1, IF(INDEX(Data_metier!$H:$H,MATCH($A4,Data_metier!$B:$B,0))-INDEX(Data_metier!$H:$H,MATCH(H$1,Data_metier!$B:$B,0))> 1, 2, 0))) -> -1 | I4: =IF(INDEX(Data_metier!$H:$H,MATCH($A4,Data_metier!$B:$B,0))-INDEX(Data_metier!$H:$H,MATCH(I$1,Data_metier!$B:$B,0))< 0,-1, IF(AND(INDEX(Data_metier!$H:$H,MATCH($A4,Data_metier!$B:$B,0))-INDEX(Data_metier!$H:$H,MATCH(I$1,Data_metier!$B:$B,0))> 0, INDEX(Data_metier!$H:$H,MATCH($A4,Data_metier!$B:$B,0))-INDEX(Data_metier!$H:$H,MATCH(I$1,Data_metier!$B:$B,0))<=1), 1, IF(INDEX(Data_metier!$H:$H,MATCH($A4,Data_metier!$B:$B,0))-INDEX(Data_metier!$H:$H,MATCH(I$1,Data_metier!$B:$B,0))> 1, 2, 0))) -> 0 | ... AD4: =IF(INDEX(Data_metier!$H:$H,MATCH($A4,Data_metier!$B:$B,0))-INDEX(Data_metier!$H:$H,MATCH(AD$1,Data_metier!$B:$B,0))< 0,-1, IF(AND(INDEX(Data_metier!$H:$H,MATCH($A4,Data_metier!$B:$B,0))-INDEX(Data_metier!$H:$H,MATCH(AD$1,Data_metier!$B:$B,0))> 0, INDEX(Data_metier!$H:$H,MATCH($A4,Data_metier!$B:$B,0))-INDEX(Data_metier!$H:$H,MATCH(AD$1,Data_metier!$B:$B,0))<=1), 1, IF(INDEX(Data_metier!$H:$H,MATCH($A4,Data_metier!$B:$B,0))-INDEX(Data_metier!$H:$H,MATCH(AD$1,Data_metier!$B:$B,0))> 1, 2, 0))) -> -1
A5: Manager(euse) logistique | B5: =IF(INDEX(Data_metier!$H:$H,MATCH($A5,Data_metier!$B:$B,0))-INDEX(Data_metier!$H:$H,MATCH(B$1,Data_metier!$B:$B,0))< 0,-1, IF(AND(INDEX(Data_metier!$H:$H,MATCH($A5,Data_metier!$B:$B,0))-INDEX(Data_metier!$H:$H,MATCH(B$1,Data_metier!$B:$B,0))> 0, INDEX(Data_metier!$H:$H,MATCH($A5,Data_metier!$B:$B,0))-INDEX(Data_metier!$H:$H,MATCH(B$1,Data_metier!$B:$B,0))<=1), 1, IF(INDEX(Data_metier!$H:$H,MATCH($A5,Data_metier!$B:$B,0))-INDEX(Data_metier!$H:$H,MATCH(B$1,Data_metier!$B:$B,0))> 1, 2, 0))) -> 2 | C5: =IF(INDEX(Data_metier!$H:$H,MATCH($A5,Data_metier!$B:$B,0))-INDEX(Data_metier!$H:$H,MATCH(C$1,Data_metier!$B:$B,0))< 0,-1, IF(AND(INDEX(Data_metier!$H:$H,MATCH($A5,Data_metier!$B:$B,0))-INDEX(Data_metier!$H:$H,MATCH(C$1,Data_metier!$B:$B,0))> 0, INDEX(Data_metier!$H:$H,MATCH($A5,Data_metier!$B:$B,0))-INDEX(Data_metier!$H:$H,MATCH(C$1,Data_metier!$B:$B,0))<=1), 1, IF(INDEX(Data_metier!$H:$H,MATCH($A5,Data_metier!$B:$B,0))-INDEX(Data_metier!$H:$H,MATCH(C$1,Data_metier!$B:$B,0))> 1, 2, 0))) -> 2 | D5: =IF(INDEX(Data_metier!$H:$H,MATCH($A5,Data_metier!$B:$B,0))-INDEX(Data_metier!$H:$H,MATCH(D$1,Data_metier!$B:$B,0))< 0,-1, IF(AND(INDEX(Data_metier!$H:$H,MATCH($A5,Data_metier!$B:$B,0))-INDEX(Data_metier!$H:$H,MATCH(D$1,Data_metier!$B:$B,0))> 0, INDEX(Data_metier!$H:$H,MATCH($A5,Data_metier!$B:$B,0))-INDEX(Data_metier!$H:$H,MATCH(D$1,Data_metier!$B:$B,0))<=1), 1, IF(INDEX(Data_metier!$H:$H,MATCH($A5,Data_metier!$B:$B,0))-INDEX(Data_metier!$H:$H,MATCH(D$1,Data_metier!$B:$B,0))> 1, 2, 0))) -> 2 | E5: =IF(INDEX(Data_metier!$H:$H,MATCH($A5,Data_metier!$B:$B,0))-INDEX(Data_metier!$H:$H,MATCH(E$1,Data_metier!$B:$B,0))< 0,-1, IF(AND(INDEX(Data_metier!$H:$H,MATCH($A5,Data_metier!$B:$B,0))-INDEX(Data_metier!$H:$H,MATCH(E$1,Data_metier!$B:$B,0))> 0, INDEX(Data_metier!$H:$H,MATCH($A5,Data_metier!$B:$B,0))-INDEX(Data_metier!$H:$H,MATCH(E$1,Data_metier!$B:$B,0))<=1), 1, IF(INDEX(Data_metier!$H:$H,MATCH($A5,Data_metier!$B:$B,0))-INDEX(Data_metier!$H:$H,MATCH(E$1,Data_metier!$B:$B,0))> 1, 2, 0))) -> 0 | F5: =IF(INDEX(Data_metier!$H:$H,MATCH($A5,Data_metier!$B:$B,0))-INDEX(Data_metier!$H:$H,MATCH(F$1,Data_metier!$B:$B,0))< 0,-1, IF(AND(INDEX(Data_metier!$H:$H,MATCH($A5,Data_metier!$B:$B,0))-INDEX(Data_metier!$H:$H,MATCH(F$1,Data_metier!$B:$B,0))> 0, INDEX(Data_metier!$H:$H,MATCH($A5,Data_metier!$B:$B,0))-INDEX(Data_metier!$H:$H,MATCH(F$1,Data_metier!$B:$B,0))<=1), 1, IF(INDEX(Data_metier!$H:$H,MATCH($A5,Data_metier!$B:$B,0))-INDEX(Data_metier!$H:$H,MATCH(F$1,Data_metier!$B:$B,0))> 1, 2, 0))) -> -1 | G5: =IF(INDEX(Data_metier!$H:$H,MATCH($A5,Data_metier!$B:$B,0))-INDEX(Data_metier!$H:$H,MATCH(G$1,Data_metier!$B:$B,0))< 0,-1, IF(AND(INDEX(Data_metier!$H:$H,MATCH($A5,Data_metier!$B:$B,0))-INDEX(Data_metier!$H:$H,MATCH(G$1,Data_metier!$B:$B,0))> 0, INDEX(Data_metier!$H:$H,MATCH($A5,Data_metier!$B:$B,0))-INDEX(Data_metier!$H:$H,MATCH(G$1,Data_metier!$B:$B,0))<=1), 1, IF(INDEX(Data_metier!$H:$H,MATCH($A5,Data_metier!$B:$B,0))-INDEX(Data_metier!$H:$H,MATCH(G$1,Data_metier!$B:$B,0))> 1, 2, 0))) -> -1 | H5: =IF(INDEX(Data_metier!$H:$H,MATCH($A5,Data_metier!$B:$B,0))-INDEX(Data_metier!$H:$H,MATCH(H$1,Data_metier!$B:$B,0))< 0,-1, IF(AND(INDEX(Data_metier!$H:$H,MATCH($A5,Data_metier!$B:$B,0))-INDEX(Data_metier!$H:$H,MATCH(H$1,Data_metier!$B:$B,0))> 0, INDEX(Data_metier!$H:$H,MATCH($A5,Data_metier!$B:$B,0))-INDEX(Data_metier!$H:$H,MATCH(H$1,Data_metier!$B:$B,0))<=1), 1, IF(INDEX(Data_metier!$H:$H,MATCH($A5,Data_metier!$B:$B,0))-INDEX(Data_metier!$H:$H,MATCH(H$1,Data_metier!$B:$B,0))> 1, 2, 0))) -> -1 | I5: =IF(INDEX(Data_metier!$H:$H,MATCH($A5,Data_metier!$B:$B,0))-INDEX(Data_metier!$H:$H,MATCH(I$1,Data_metier!$B:$B,0))< 0,-1, IF(AND(INDEX(Data_metier!$H:$H,MATCH($A5,Data_metier!$B:$B,0))-INDEX(Data_metier!$H:$H,MATCH(I$1,Data_metier!$B:$B,0))> 0, INDEX(Data_metier!$H:$H,MATCH($A5,Data_metier!$B:$B,0))-INDEX(Data_metier!$H:$H,MATCH(I$1,Data_metier!$B:$B,0))<=1), 1, IF(INDEX(Data_metier!$H:$H,MATCH($A5,Data_metier!$B:$B,0))-INDEX(Data_metier!$H:$H,MATCH(I$1,Data_metier!$B:$B,0))> 1, 2, 0))) -> 2 | ... AD5: =IF(INDEX(Data_metier!$H:$H,MATCH($A5,Data_metier!$B:$B,0))-INDEX(Data_metier!$H:$H,MATCH(AD$1,Data_metier!$B:$B,0))< 0,-1, IF(AND(INDEX(Data_metier!$H:$H,MATCH($A5,Data_metier!$B:$B,0))-INDEX(Data_metier!$H:$H,MATCH(AD$1,Data_metier!$B:$B,0))> 0, INDEX(Data_metier!$H:$H,MATCH($A5,Data_metier!$B:$B,0))-INDEX(Data_metier!$H:$H,MATCH(AD$1,Data_metier!$B:$B,0))<=1), 1, IF(INDEX(Data_metier!$H:$H,MATCH($A5,Data_metier!$B:$B,0))-INDEX(Data_metier!$H:$H,MATCH(AD$1,Data_metier!$B:$B,0))> 1, 2, 0))) -> 1
A6: Maître(sse) de chai | B6: =IF(INDEX(Data_metier!$H:$H,MATCH($A6,Data_metier!$B:$B,0))-INDEX(Data_metier!$H:$H,MATCH(B$1,Data_metier!$B:$B,0))< 0,-1, IF(AND(INDEX(Data_metier!$H:$H,MATCH($A6,Data_metier!$B:$B,0))-INDEX(Data_metier!$H:$H,MATCH(B$1,Data_metier!$B:$B,0))> 0, INDEX(Data_metier!$H:$H,MATCH($A6,Data_metier!$B:$B,0))-INDEX(Data_metier!$H:$H,MATCH(B$1,Data_metier!$B:$B,0))<=1), 1, IF(INDEX(Data_metier!$H:$H,MATCH($A6,Data_metier!$B:$B,0))-INDEX(Data_metier!$H:$H,MATCH(B$1,Data_metier!$B:$B,0))> 1, 2, 0))) -> 2 | C6: =IF(INDEX(Data_metier!$H:$H,MATCH($A6,Data_metier!$B:$B,0))-INDEX(Data_metier!$H:$H,MATCH(C$1,Data_metier!$B:$B,0))< 0,-1, IF(AND(INDEX(Data_metier!$H:$H,MATCH($A6,Data_metier!$B:$B,0))-INDEX(Data_metier!$H:$H,MATCH(C$1,Data_metier!$B:$B,0))> 0, INDEX(Data_metier!$H:$H,MATCH($A6,Data_metier!$B:$B,0))-INDEX(Data_metier!$H:$H,MATCH(C$1,Data_metier!$B:$B,0))<=1), 1, IF(INDEX(Data_metier!$H:$H,MATCH($A6,Data_metier!$B:$B,0))-INDEX(Data_metier!$H:$H,MATCH(C$1,Data_metier!$B:$B,0))> 1, 2, 0))) -> 2 | D6: =IF(INDEX(Data_metier!$H:$H,MATCH($A6,Data_metier!$B:$B,0))-INDEX(Data_metier!$H:$H,MATCH(D$1,Data_metier!$B:$B,0))< 0,-1, IF(AND(INDEX(Data_metier!$H:$H,MATCH($A6,Data_metier!$B:$B,0))-INDEX(Data_metier!$H:$H,MATCH(D$1,Data_metier!$B:$B,0))> 0, INDEX(Data_metier!$H:$H,MATCH($A6,Data_metier!$B:$B,0))-INDEX(Data_metier!$H:$H,MATCH(D$1,Data_metier!$B:$B,0))<=1), 1, IF(INDEX(Data_metier!$H:$H,MATCH($A6,Data_metier!$B:$B,0))-INDEX(Data_metier!$H:$H,MATCH(D$1,Data_metier!$B:$B,0))> 1, 2, 0))) -> 2 | E6: =IF(INDEX(Data_metier!$H:$H,MATCH($A6,Data_metier!$B:$B,0))-INDEX(Data_metier!$H:$H,MATCH(E$1,Data_metier!$B:$B,0))< 0,-1, IF(AND(INDEX(Data_metier!$H:$H,MATCH($A6,Data_metier!$B:$B,0))-INDEX(Data_metier!$H:$H,MATCH(E$1,Data_metier!$B:$B,0))> 0, INDEX(Data_metier!$H:$H,MATCH($A6,Data_metier!$B:$B,0))-INDEX(Data_metier!$H:$H,MATCH(E$1,Data_metier!$B:$B,0))<=1), 1, IF(INDEX(Data_metier!$H:$H,MATCH($A6,Data_metier!$B:$B,0))-INDEX(Data_metier!$H:$H,MATCH(E$1,Data_metier!$B:$B,0))> 1, 2, 0))) -> 1 | F6: =IF(INDEX(Data_metier!$H:$H,MATCH($A6,Data_metier!$B:$B,0))-INDEX(Data_metier!$H:$H,MATCH(F$1,Data_metier!$B:$B,0))< 0,-1, IF(AND(INDEX(Data_metier!$H:$H,MATCH($A6,Data_metier!$B:$B,0))-INDEX(Data_metier!$H:$H,MATCH(F$1,Data_metier!$B:$B,0))> 0, INDEX(Data_metier!$H:$H,MATCH($A6,Data_metier!$B:$B,0))-INDEX(Data_metier!$H:$H,MATCH(F$1,Data_metier!$B:$B,0))<=1), 1, IF(INDEX(Data_metier!$H:$H,MATCH($A6,Data_metier!$B:$B,0))-INDEX(Data_metier!$H:$H,MATCH(F$1,Data_metier!$B:$B,0))> 1, 2, 0))) -> 0 | G6: =IF(INDEX(Data_metier!$H:$H,MATCH($A6,Data_metier!$B:$B,0))-INDEX(Data_metier!$H:$H,MATCH(G$1,Data_metier!$B:$B,0))< 0,-1, IF(AND(INDEX(Data_metier!$H:$H,MATCH($A6,Data_metier!$B:$B,0))-INDEX(Data_metier!$H:$H,MATCH(G$1,Data_metier!$B:$B,0))> 0, INDEX(Data_metier!$H:$H,MATCH($A6,Data_metier!$B:$B,0))-INDEX(Data_metier!$H:$H,MATCH(G$1,Data_metier!$B:$B,0))<=1), 1, IF(INDEX(Data_metier!$H:$H,MATCH($A6,Data_metier!$B:$B,0))-INDEX(Data_metier!$H:$H,MATCH(G$1,Data_metier!$B:$B,0))> 1, 2, 0))) -> 0 | H6: =IF(INDEX(Data_metier!$H:$H,MATCH($A6,Data_metier!$B:$B,0))-INDEX(Data_metier!$H:$H,MATCH(H$1,Data_metier!$B:$B,0))< 0,-1, IF(AND(INDEX(Data_metier!$H:$H,MATCH($A6,Data_metier!$B:$B,0))-INDEX(Data_metier!$H:$H,MATCH(H$1,Data_metier!$B:$B,0))> 0, INDEX(Data_metier!$H:$H,MATCH($A6,Data_metier!$B:$B,0))-INDEX(Data_metier!$H:$H,MATCH(H$1,Data_metier!$B:$B,0))<=1), 1, IF(INDEX(Data_metier!$H:$H,MATCH($A6,Data_metier!$B:$B,0))-INDEX(Data_metier!$H:$H,MATCH(H$1,Data_metier!$B:$B,0))> 1, 2, 0))) -> 0 | I6: =IF(INDEX(Data_metier!$H:$H,MATCH($A6,Data_metier!$B:$B,0))-INDEX(Data_metier!$H:$H,MATCH(I$1,Data_metier!$B:$B,0))< 0,-1, IF(AND(INDEX(Data_metier!$H:$H,MATCH($A6,Data_metier!$B:$B,0))-INDEX(Data_metier!$H:$H,MATCH(I$1,Data_metier!$B:$B,0))> 0, INDEX(Data_metier!$H:$H,MATCH($A6,Data_metier!$B:$B,0))-INDEX(Data_metier!$H:$H,MATCH(I$1,Data_metier!$B:$B,0))<=1), 1, IF(INDEX(Data_metier!$H:$H,MATCH($A6,Data_metier!$B:$B,0))-INDEX(Data_metier!$H:$H,MATCH(I$1,Data_metier!$B:$B,0))> 1, 2, 0))) -> 2 | ... AD6: =IF(INDEX(Data_metier!$H:$H,MATCH($A6,Data_metier!$B:$B,0))-INDEX(Data_metier!$H:$H,MATCH(AD$1,Data_metier!$B:$B,0))< 0,-1, IF(AND(INDEX(Data_metier!$H:$H,MATCH($A6,Data_metier!$B:$B,0))-INDEX(Data_metier!$H:$H,MATCH(AD$1,Data_metier!$B:$B,0))> 0, INDEX(Data_metier!$H:$H,MATCH($A6,Data_metier!$B:$B,0))-INDEX(Data_metier!$H:$H,MATCH(AD$1,Data_metier!$B:$B,0))<=1), 1, IF(INDEX(Data_metier!$H:$H,MATCH($A6,Data_metier!$B:$B,0))-INDEX(Data_metier!$H:$H,MATCH(AD$1,Data_metier!$B:$B,0))> 1, 2, 0))) -> 2
A7: Superviseur(se) de production (fabrication / conditionnement) | B7: =IF(INDEX(Data_metier!$H:$H,MATCH($A7,Data_metier!$B:$B,0))-INDEX(Data_metier!$H:$H,MATCH(B$1,Data_metier!$B:$B,0))< 0,-1, IF(AND(INDEX(Data_metier!$H:$H,MATCH($A7,Data_metier!$B:$B,0))-INDEX(Data_metier!$H:$H,MATCH(B$1,Data_metier!$B:$B,0))> 0, INDEX(Data_metier!$H:$H,MATCH($A7,Data_metier!$B:$B,0))-INDEX(Data_metier!$H:$H,MATCH(B$1,Data_metier!$B:$B,0))<=1), 1, IF(INDEX(Data_metier!$H:$H,MATCH($A7,Data_metier!$B:$B,0))-INDEX(Data_metier!$H:$H,MATCH(B$1,Data_metier!$B:$B,0))> 1, 2, 0))) -> 2 | C7: =IF(INDEX(Data_metier!$H:$H,MATCH($A7,Data_metier!$B:$B,0))-INDEX(Data_metier!$H:$H,MATCH(C$1,Data_metier!$B:$B,0))< 0,-1, IF(AND(INDEX(Data_metier!$H:$H,MATCH($A7,Data_metier!$B:$B,0))-INDEX(Data_metier!$H:$H,MATCH(C$1,Data_metier!$B:$B,0))> 0, INDEX(Data_metier!$H:$H,MATCH($A7,Data_metier!$B:$B,0))-INDEX(Data_metier!$H:$H,MATCH(C$1,Data_metier!$B:$B,0))<=1), 1, IF(INDEX(Data_metier!$H:$H,MATCH($A7,Data_metier!$B:$B,0))-INDEX(Data_metier!$H:$H,MATCH(C$1,Data_metier!$B:$B,0))> 1, 2, 0))) -> 2 | D7: =IF(INDEX(Data_metier!$H:$H,MATCH($A7,Data_metier!$B:$B,0))-INDEX(Data_metier!$H:$H,MATCH(D$1,Data_metier!$B:$B,0))< 0,-1, IF(AND(INDEX(Data_metier!$H:$H,MATCH($A7,Data_metier!$B:$B,0))-INDEX(Data_metier!$H:$H,MATCH(D$1,Data_metier!$B:$B,0))> 0, INDEX(Data_metier!$H:$H,MATCH($A7,Data_metier!$B:$B,0))-INDEX(Data_metier!$H:$H,MATCH(D$1,Data_metier!$B:$B,0))<=1), 1, IF(INDEX(Data_metier!$H:$H,MATCH($A7,Data_metier!$B:$B,0))-INDEX(Data_metier!$H:$H,MATCH(D$1,Data_metier!$B:$B,0))> 1, 2, 0))) -> 2 | E7: =IF(INDEX(Data_metier!$H:$H,MATCH($A7,Data_metier!$B:$B,0))-INDEX(Data_metier!$H:$H,MATCH(E$1,Data_metier!$B:$B,0))< 0,-1, IF(AND(INDEX(Data_metier!$H:$H,MATCH($A7,Data_metier!$B:$B,0))-INDEX(Data_metier!$H:$H,MATCH(E$1,Data_metier!$B:$B,0))> 0, INDEX(Data_metier!$H:$H,MATCH($A7,Data_metier!$B:$B,0))-INDEX(Data_metier!$H:$H,MATCH(E$1,Data_metier!$B:$B,0))<=1), 1, IF(INDEX(Data_metier!$H:$H,MATCH($A7,Data_metier!$B:$B,0))-INDEX(Data_metier!$H:$H,MATCH(E$1,Data_metier!$B:$B,0))> 1, 2, 0))) -> 1 | F7: =IF(INDEX(Data_metier!$H:$H,MATCH($A7,Data_metier!$B:$B,0))-INDEX(Data_metier!$H:$H,MATCH(F$1,Data_metier!$B:$B,0))< 0,-1, IF(AND(INDEX(Data_metier!$H:$H,MATCH($A7,Data_metier!$B:$B,0))-INDEX(Data_metier!$H:$H,MATCH(F$1,Data_metier!$B:$B,0))> 0, INDEX(Data_metier!$H:$H,MATCH($A7,Data_metier!$B:$B,0))-INDEX(Data_metier!$H:$H,MATCH(F$1,Data_metier!$B:$B,0))<=1), 1, IF(INDEX(Data_metier!$H:$H,MATCH($A7,Data_metier!$B:$B,0))-INDEX(Data_metier!$H:$H,MATCH(F$1,Data_metier!$B:$B,0))> 1, 2, 0))) -> 0 | G7: =IF(INDEX(Data_metier!$H:$H,MATCH($A7,Data_metier!$B:$B,0))-INDEX(Data_metier!$H:$H,MATCH(G$1,Data_metier!$B:$B,0))< 0,-1, IF(AND(INDEX(Data_metier!$H:$H,MATCH($A7,Data_metier!$B:$B,0))-INDEX(Data_metier!$H:$H,MATCH(G$1,Data_metier!$B:$B,0))> 0, INDEX(Data_metier!$H:$H,MATCH($A7,Data_metier!$B:$B,0))-INDEX(Data_metier!$H:$H,MATCH(G$1,Data_metier!$B:$B,0))<=1), 1, IF(INDEX(Data_metier!$H:$H,MATCH($A7,Data_metier!$B:$B,0))-INDEX(Data_metier!$H:$H,MATCH(G$1,Data_metier!$B:$B,0))> 1, 2, 0))) -> 0 | H7: =IF(INDEX(Data_metier!$H:$H,MATCH($A7,Data_metier!$B:$B,0))-INDEX(Data_metier!$H:$H,MATCH(H$1,Data_metier!$B:$B,0))< 0,-1, IF(AND(INDEX(Data_metier!$H:$H,MATCH($A7,Data_metier!$B:$B,0))-INDEX(Data_metier!$H:$H,MATCH(H$1,Data_metier!$B:$B,0))> 0, INDEX(Data_metier!$H:$H,MATCH($A7,Data_metier!$B:$B,0))-INDEX(Data_metier!$H:$H,MATCH(H$1,Data_metier!$B:$B,0))<=1), 1, IF(INDEX(Data_metier!$H:$H,MATCH($A7,Data_metier!$B:$B,0))-INDEX(Data_metier!$H:$H,MATCH(H$1,Data_metier!$B:$B,0))> 1, 2, 0))) -> 0 | I7: =IF(INDEX(Data_metier!$H:$H,MATCH($A7,Data_metier!$B:$B,0))-INDEX(Data_metier!$H:$H,MATCH(I$1,Data_metier!$B:$B,0))< 0,-1, IF(AND(INDEX(Data_metier!$H:$H,MATCH($A7,Data_metier!$B:$B,0))-INDEX(Data_metier!$H:$H,MATCH(I$1,Data_metier!$B:$B,0))> 0, INDEX(Data_metier!$H:$H,MATCH($A7,Data_metier!$B:$B,0))-INDEX(Data_metier!$H:$H,MATCH(I$1,Data_metier!$B:$B,0))<=1), 1, IF(INDEX(Data_metier!$H:$H,MATCH($A7,Data_metier!$B:$B,0))-INDEX(Data_metier!$H:$H,MATCH(I$1,Data_metier!$B:$B,0))> 1, 2, 0))) -> 2 | ... AD7: =IF(INDEX(Data_metier!$H:$H,MATCH($A7,Data_metier!$B:$B,0))-INDEX(Data_metier!$H:$H,MATCH(AD$1,Data_metier!$B:$B,0))< 0,-1, IF(AND(INDEX(Data_metier!$H:$H,MATCH($A7,Data_metier!$B:$B,0))-INDEX(Data_metier!$H:$H,MATCH(AD$1,Data_metier!$B:$B,0))> 0, INDEX(Data_metier!$H:$H,MATCH($A7,Data_metier!$B:$B,0))-INDEX(Data_metier!$H:$H,MATCH(AD$1,Data_metier!$B:$B,0))<=1), 1, IF(INDEX(Data_metier!$H:$H,MATCH($A7,Data_metier!$B:$B,0))-INDEX(Data_metier!$H:$H,MATCH(AD$1,Data_metier!$B:$B,0))> 1, 2, 0))) -> 2
A8: Spécialiste planning / ordonnancement | B8: =IF(INDEX(Data_metier!$H:$H,MATCH($A8,Data_metier!$B:$B,0))-INDEX(Data_metier!$H:$H,MATCH(B$1,Data_metier!$B:$B,0))< 0,-1, IF(AND(INDEX(Data_metier!$H:$H,MATCH($A8,Data_metier!$B:$B,0))-INDEX(Data_metier!$H:$H,MATCH(B$1,Data_metier!$B:$B,0))> 0, INDEX(Data_metier!$H:$H,MATCH($A8,Data_metier!$B:$B,0))-INDEX(Data_metier!$H:$H,MATCH(B$1,Data_metier!$B:$B,0))<=1), 1, IF(INDEX(Data_metier!$H:$H,MATCH($A8,Data_metier!$B:$B,0))-INDEX(Data_metier!$H:$H,MATCH(B$1,Data_metier!$B:$B,0))> 1, 2, 0))) -> 2 | C8: =IF(INDEX(Data_metier!$H:$H,MATCH($A8,Data_metier!$B:$B,0))-INDEX(Data_metier!$H:$H,MATCH(C$1,Data_metier!$B:$B,0))< 0,-1, IF(AND(INDEX(Data_metier!$H:$H,MATCH($A8,Data_metier!$B:$B,0))-INDEX(Data_metier!$H:$H,MATCH(C$1,Data_metier!$B:$B,0))> 0, INDEX(Data_metier!$H:$H,MATCH($A8,Data_metier!$B:$B,0))-INDEX(Data_metier!$H:$H,MATCH(C$1,Data_metier!$B:$B,0))<=1), 1, IF(INDEX(Data_metier!$H:$H,MATCH($A8,Data_metier!$B:$B,0))-INDEX(Data_metier!$H:$H,MATCH(C$1,Data_metier!$B:$B,0))> 1, 2, 0))) -> 2 | D8: =IF(INDEX(Data_metier!$H:$H,MATCH($A8,Data_metier!$B:$B,0))-INDEX(Data_metier!$H:$H,MATCH(D$1,Data_metier!$B:$B,0))< 0,-1, IF(AND(INDEX(Data_metier!$H:$H,MATCH($A8,Data_metier!$B:$B,0))-INDEX(Data_metier!$H:$H,MATCH(D$1,Data_metier!$B:$B,0))> 0, INDEX(Data_metier!$H:$H,MATCH($A8,Data_metier!$B:$B,0))-INDEX(Data_metier!$H:$H,MATCH(D$1,Data_metier!$B:$B,0))<=1), 1, IF(INDEX(Data_metier!$H:$H,MATCH($A8,Data_metier!$B:$B,0))-INDEX(Data_metier!$H:$H,MATCH(D$1,Data_metier!$B:$B,0))> 1, 2, 0))) -> 2 | E8: =IF(INDEX(Data_metier!$H:$H,MATCH($A8,Data_metier!$B:$B,0))-INDEX(Data_metier!$H:$H,MATCH(E$1,Data_metier!$B:$B,0))< 0,-1, IF(AND(INDEX(Data_metier!$H:$H,MATCH($A8,Data_metier!$B:$B,0))-INDEX(Data_metier!$H:$H,MATCH(E$1,Data_metier!$B:$B,0))> 0, INDEX(Data_metier!$H:$H,MATCH($A8,Data_metier!$B:$B,0))-INDEX(Data_metier!$H:$H,MATCH(E$1,Data_metier!$B:$B,0))<=1), 1, IF(INDEX(Data_metier!$H:$H,MATCH($A8,Data_metier!$B:$B,0))-INDEX(Data_metier!$H:$H,MATCH(E$1,Data_metier!$B:$B,0))> 1, 2, 0))) -> 1 | F8: =IF(INDEX(Data_metier!$H:$H,MATCH($A8,Data_metier!$B:$B,0))-INDEX(Data_metier!$H:$H,MATCH(F$1,Data_metier!$B:$B,0))< 0,-1, IF(AND(INDEX(Data_metier!$H:$H,MATCH($A8,Data_metier!$B:$B,0))-INDEX(Data_metier!$H:$H,MATCH(F$1,Data_metier!$B:$B,0))> 0, INDEX(Data_metier!$H:$H,MATCH($A8,Data_metier!$B:$B,0))-INDEX(Data_metier!$H:$H,MATCH(F$1,Data_metier!$B:$B,0))<=1), 1, IF(INDEX(Data_metier!$H:$H,MATCH($A8,Data_metier!$B:$B,0))-INDEX(Data_metier!$H:$H,MATCH(F$1,Data_metier!$B:$B,0))> 1, 2, 0))) -> 0 | G8: =IF(INDEX(Data_metier!$H:$H,MATCH($A8,Data_metier!$B:$B,0))-INDEX(Data_metier!$H:$H,MATCH(G$1,Data_metier!$B:$B,0))< 0,-1, IF(AND(INDEX(Data_metier!$H:$H,MATCH($A8,Data_metier!$B:$B,0))-INDEX(Data_metier!$H:$H,MATCH(G$1,Data_metier!$B:$B,0))> 0, INDEX(Data_metier!$H:$H,MATCH($A8,Data_metier!$B:$B,0))-INDEX(Data_metier!$H:$H,MATCH(G$1,Data_metier!$B:$B,0))<=1), 1, IF(INDEX(Data_metier!$H:$H,MATCH($A8,Data_metier!$B:$B,0))-INDEX(Data_metier!$H:$H,MATCH(G$1,Data_metier!$B:$B,0))> 1, 2, 0))) -> 0 | H8: =IF(INDEX(Data_metier!$H:$H,MATCH($A8,Data_metier!$B:$B,0))-INDEX(Data_metier!$H:$H,MATCH(H$1,Data_metier!$B:$B,0))< 0,-1, IF(AND(INDEX(Data_metier!$H:$H,MATCH($A8,Data_metier!$B:$B,0))-INDEX(Data_metier!$H:$H,MATCH(H$1,Data_metier!$B:$B,0))> 0, INDEX(Data_metier!$H:$H,MATCH($A8,Data_metier!$B:$B,0))-INDEX(Data_metier!$H:$H,MATCH(H$1,Data_metier!$B:$B,0))<=1), 1, IF(INDEX(Data_metier!$H:$H,MATCH($A8,Data_metier!$B:$B,0))-INDEX(Data_metier!$H:$H,MATCH(H$1,Data_metier!$B:$B,0))> 1, 2, 0))) -> 0 | I8: =IF(INDEX(Data_metier!$H:$H,MATCH($A8,Data_metier!$B:$B,0))-INDEX(Data_metier!$H:$H,MATCH(I$1,Data_metier!$B:$B,0))< 0,-1, IF(AND(INDEX(Data_metier!$H:$H,MATCH($A8,Data_metier!$B:$B,0))-INDEX(Data_metier!$H:$H,MATCH(I$1,Data_metier!$B:$B,0))> 0, INDEX(Data_metier!$H:$H,MATCH($A8,Data_metier!$B:$B,0))-INDEX(Data_metier!$H:$H,MATCH(I$1,Data_metier!$B:$B,0))<=1), 1, IF(INDEX(Data_metier!$H:$H,MATCH($A8,Data_metier!$B:$B,0))-INDEX(Data_metier!$H:$H,MATCH(I$1,Data_metier!$B:$B,0))> 1, 2, 0))) -> 2 | ... AD8: =IF(INDEX(Data_metier!$H:$H,MATCH($A8,Data_metier!$B:$B,0))-INDEX(Data_metier!$H:$H,MATCH(AD$1,Data_metier!$B:$B,0))< 0,-1, IF(AND(INDEX(Data_metier!$H:$H,MATCH($A8,Data_metier!$B:$B,0))-INDEX(Data_metier!$H:$H,MATCH(AD$1,Data_metier!$B:$B,0))> 0, INDEX(Data_metier!$H:$H,MATCH($A8,Data_metier!$B:$B,0))-INDEX(Data_metier!$H:$H,MATCH(AD$1,Data_metier!$B:$B,0))<=1), 1, IF(INDEX(Data_metier!$H:$H,MATCH($A8,Data_metier!$B:$B,0))-INDEX(Data_metier!$H:$H,MATCH(AD$1,Data_metier!$B:$B,0))> 1, 2, 0))) -> 2
A9: Opérateur(trice) logistique | B9: =IF(INDEX(Data_metier!$H:$H,MATCH($A9,Data_metier!$B:$B,0))-INDEX(Data_metier!$H:$H,MATCH(B$1,Data_metier!$B:$B,0))< 0,-1, IF(AND(INDEX(Data_metier!$H:$H,MATCH($A9,Data_metier!$B:$B,0))-INDEX(Data_metier!$H:$H,MATCH(B$1,Data_metier!$B:$B,0))> 0, INDEX(Data_metier!$H:$H,MATCH($A9,Data_metier!$B:$B,0))-INDEX(Data_metier!$H:$H,MATCH(B$1,Data_metier!$B:$B,0))<=1), 1, IF(INDEX(Data_metier!$H:$H,MATCH($A9,Data_metier!$B:$B,0))-INDEX(Data_metier!$H:$H,MATCH(B$1,Data_metier!$B:$B,0))> 1, 2, 0))) -> -1 | C9: =IF(INDEX(Data_metier!$H:$H,MATCH($A9,Data_metier!$B:$B,0))-INDEX(Data_metier!$H:$H,MATCH(C$1,Data_metier!$B:$B,0))< 0,-1, IF(AND(INDEX(Data_metier!$H:$H,MATCH($A9,Data_metier!$B:$B,0))-INDEX(Data_metier!$H:$H,MATCH(C$1,Data_metier!$B:$B,0))> 0, INDEX(Data_metier!$H:$H,MATCH($A9,Data_metier!$B:$B,0))-INDEX(Data_metier!$H:$H,MATCH(C$1,Data_metier!$B:$B,0))<=1), 1, IF(INDEX(Data_metier!$H:$H,MATCH($A9,Data_metier!$B:$B,0))-INDEX(Data_metier!$H:$H,MATCH(C$1,Data_metier!$B:$B,0))> 1, 2, 0))) -> -1 | D9: =IF(INDEX(Data_metier!$H:$H,MATCH($A9,Data_metier!$B:$B,0))-INDEX(Data_metier!$H:$H,MATCH(D$1,Data_metier!$B:$B,0))< 0,-1, IF(AND(INDEX(Data_metier!$H:$H,MATCH($A9,Data_metier!$B:$B,0))-INDEX(Data_metier!$H:$H,MATCH(D$1,Data_metier!$B:$B,0))> 0, INDEX(Data_metier!$H:$H,MATCH($A9,Data_metier!$B:$B,0))-INDEX(Data_metier!$H:$H,MATCH(D$1,Data_metier!$B:$B,0))<=1), 1, IF(INDEX(Data_metier!$H:$H,MATCH($A9,Data_metier!$B:$B,0))-INDEX(Data_metier!$H:$H,MATCH(D$1,Data_metier!$B:$B,0))> 1, 2, 0))) -> 0 | E9: =IF(INDEX(Data_metier!$H:$H,MATCH($A9,Data_metier!$B:$B,0))-INDEX(Data_metier!$H:$H,MATCH(E$1,Data_metier!$B:$B,0))< 0,-1, IF(AND(INDEX(Data_metier!$H:$H,MATCH($A9,Data_metier!$B:$B,0))-INDEX(Data_metier!$H:$H,MATCH(E$1,Data_metier!$B:$B,0))> 0, INDEX(Data_metier!$H:$H,MATCH($A9,Data_metier!$B:$B,0))-INDEX(Data_metier!$H:$H,MATCH(E$1,Data_metier!$B:$B,0))<=1), 1, IF(INDEX(Data_metier!$H:$H,MATCH($A9,Data_metier!$B:$B,0))-INDEX(Data_metier!$H:$H,MATCH(E$1,Data_metier!$B:$B,0))> 1, 2, 0))) -> -1 | F9: =IF(INDEX(Data_metier!$H:$H,MATCH($A9,Data_metier!$B:$B,0))-INDEX(Data_metier!$H:$H,MATCH(F$1,Data_metier!$B:$B,0))< 0,-1, IF(AND(INDEX(Data_metier!$H:$H,MATCH($A9,Data_metier!$B:$B,0))-INDEX(Data_metier!$H:$H,MATCH(F$1,Data_metier!$B:$B,0))> 0, INDEX(Data_metier!$H:$H,MATCH($A9,Data_metier!$B:$B,0))-INDEX(Data_metier!$H:$H,MATCH(F$1,Data_metier!$B:$B,0))<=1), 1, IF(INDEX(Data_metier!$H:$H,MATCH($A9,Data_metier!$B:$B,0))-INDEX(Data_metier!$H:$H,MATCH(F$1,Data_metier!$B:$B,0))> 1, 2, 0))) -> -1 | G9: =IF(INDEX(Data_metier!$H:$H,MATCH($A9,Data_metier!$B:$B,0))-INDEX(Data_metier!$H:$H,MATCH(G$1,Data_metier!$B:$B,0))< 0,-1, IF(AND(INDEX(Data_metier!$H:$H,MATCH($A9,Data_metier!$B:$B,0))-INDEX(Data_metier!$H:$H,MATCH(G$1,Data_metier!$B:$B,0))> 0, INDEX(Data_metier!$H:$H,MATCH($A9,Data_metier!$B:$B,0))-INDEX(Data_metier!$H:$H,MATCH(G$1,Data_metier!$B:$B,0))<=1), 1, IF(INDEX(Data_metier!$H:$H,MATCH($A9,Data_metier!$B:$B,0))-INDEX(Data_metier!$H:$H,MATCH(G$1,Data_metier!$B:$B,0))> 1, 2, 0))) -> -1 | H9: =IF(INDEX(Data_metier!$H:$H,MATCH($A9,Data_metier!$B:$B,0))-INDEX(Data_metier!$H:$H,MATCH(H$1,Data_metier!$B:$B,0))< 0,-1, IF(AND(INDEX(Data_metier!$H:$H,MATCH($A9,Data_metier!$B:$B,0))-INDEX(Data_metier!$H:$H,MATCH(H$1,Data_metier!$B:$B,0))> 0, INDEX(Data_metier!$H:$H,MATCH($A9,Data_metier!$B:$B,0))-INDEX(Data_metier!$H:$H,MATCH(H$1,Data_metier!$B:$B,0))<=1), 1, IF(INDEX(Data_metier!$H:$H,MATCH($A9,Data_metier!$B:$B,0))-INDEX(Data_metier!$H:$H,MATCH(H$1,Data_metier!$B:$B,0))> 1, 2, 0))) -> -1 | I9: =IF(INDEX(Data_metier!$H:$H,MATCH($A9,Data_metier!$B:$B,0))-INDEX(Data_metier!$H:$H,MATCH(I$1,Data_metier!$B:$B,0))< 0,-1, IF(AND(INDEX(Data_metier!$H:$H,MATCH($A9,Data_metier!$B:$B,0))-INDEX(Data_metier!$H:$H,MATCH(I$1,Data_metier!$B:$B,0))> 0, INDEX(Data_metier!$H:$H,MATCH($A9,Data_metier!$B:$B,0))-INDEX(Data_metier!$H:$H,MATCH(I$1,Data_metier!$B:$B,0))<=1), 1, IF(INDEX(Data_metier!$H:$H,MATCH($A9,Data_metier!$B:$B,0))-INDEX(Data_metier!$H:$H,MATCH(I$1,Data_metier!$B:$B,0))> 1, 2, 0))) -> 0 | ... AD9: =IF(INDEX(Data_metier!$H:$H,MATCH($A9,Data_metier!$B:$B,0))-INDEX(Data_metier!$H:$H,MATCH(AD$1,Data_metier!$B:$B,0))< 0,-1, IF(AND(INDEX(Data_metier!$H:$H,MATCH($A9,Data_metier!$B:$B,0))-INDEX(Data_metier!$H:$H,MATCH(AD$1,Data_metier!$B:$B,0))> 0, INDEX(Data_metier!$H:$H,MATCH($A9,Data_metier!$B:$B,0))-INDEX(Data_metier!$H:$H,MATCH(AD$1,Data_metier!$B:$B,0))<=1), 1, IF(INDEX(Data_metier!$H:$H,MATCH($A9,Data_metier!$B:$B,0))-INDEX(Data_metier!$H:$H,MATCH(AD$1,Data_metier!$B:$B,0))> 1, 2, 0))) -> -1
A10: Logisticien(ne) approvisionneur(se) | B10: =IF(INDEX(Data_metier!$H:$H,MATCH($A10,Data_metier!$B:$B,0))-INDEX(Data_metier!$H:$H,MATCH(B$1,Data_metier!$B:$B,0))< 0,-1, IF(AND(INDEX(Data_metier!$H:$H,MATCH($A10,Data_metier!$B:$B,0))-INDEX(Data_metier!$H:$H,MATCH(B$1,Data_metier!$B:$B,0))> 0, INDEX(Data_metier!$H:$H,MATCH($A10,Data_metier!$B:$B,0))-INDEX(Data_metier!$H:$H,MATCH(B$1,Data_metier!$B:$B,0))<=1), 1, IF(INDEX(Data_metier!$H:$H,MATCH($A10,Data_metier!$B:$B,0))-INDEX(Data_metier!$H:$H,MATCH(B$1,Data_metier!$B:$B,0))> 1, 2, 0))) -> 2 | C10: =IF(INDEX(Data_metier!$H:$H,MATCH($A10,Data_metier!$B:$B,0))-INDEX(Data_metier!$H:$H,MATCH(C$1,Data_metier!$B:$B,0))< 0,-1, IF(AND(INDEX(Data_metier!$H:$H,MATCH($A10,Data_metier!$B:$B,0))-INDEX(Data_metier!$H:$H,MATCH(C$1,Data_metier!$B:$B,0))> 0, INDEX(Data_metier!$H:$H,MATCH($A10,Data_metier!$B:$B,0))-INDEX(Data_metier!$H:$H,MATCH(C$1,Data_metier!$B:$B,0))<=1), 1, IF(INDEX(Data_metier!$H:$H,MATCH($A10,Data_metier!$B:$B,0))-INDEX(Data_metier!$H:$H,MATCH(C$1,Data_metier!$B:$B,0))> 1, 2, 0))) -> 2 | D10: =IF(INDEX(Data_metier!$H:$H,MATCH($A10,Data_metier!$B:$B,0))-INDEX(Data_metier!$H:$H,MATCH(D$1,Data_metier!$B:$B,0))< 0,-1, IF(AND(INDEX(Data_metier!$H:$H,MATCH($A10,Data_metier!$B:$B,0))-INDEX(Data_metier!$H:$H,MATCH(D$1,Data_metier!$B:$B,0))> 0, INDEX(Data_metier!$H:$H,MATCH($A10,Data_metier!$B:$B,0))-INDEX(Data_metier!$H:$H,MATCH(D$1,Data_metier!$B:$B,0))<=1), 1, IF(INDEX(Data_metier!$H:$H,MATCH($A10,Data_metier!$B:$B,0))-INDEX(Data_metier!$H:$H,MATCH(D$1,Data_metier!$B:$B,0))> 1, 2, 0))) -> 2 | E10: =IF(INDEX(Data_metier!$H:$H,MATCH($A10,Data_metier!$B:$B,0))-INDEX(Data_metier!$H:$H,MATCH(E$1,Data_metier!$B:$B,0))< 0,-1, IF(AND(INDEX(Data_metier!$H:$H,MATCH($A10,Data_metier!$B:$B,0))-INDEX(Data_metier!$H:$H,MATCH(E$1,Data_metier!$B:$B,0))> 0, INDEX(Data_metier!$H:$H,MATCH($A10,Data_metier!$B:$B,0))-INDEX(Data_metier!$H:$H,MATCH(E$1,Data_metier!$B:$B,0))<=1), 1, IF(INDEX(Data_metier!$H:$H,MATCH($A10,Data_metier!$B:$B,0))-INDEX(Data_metier!$H:$H,MATCH(E$1,Data_metier!$B:$B,0))> 1, 2, 0))) -> 0 | F10: =IF(INDEX(Data_metier!$H:$H,MATCH($A10,Data_metier!$B:$B,0))-INDEX(Data_metier!$H:$H,MATCH(F$1,Data_metier!$B:$B,0))< 0,-1, IF(AND(INDEX(Data_metier!$H:$H,MATCH($A10,Data_metier!$B:$B,0))-INDEX(Data_metier!$H:$H,MATCH(F$1,Data_metier!$B:$B,0))> 0, INDEX(Data_metier!$H:$H,MATCH($A10,Data_metier!$B:$B,0))-INDEX(Data_metier!$H:$H,MATCH(F$1,Data_metier!$B:$B,0))<=1), 1, IF(INDEX(Data_metier!$H:$H,MATCH($A10,Data_metier!$B:$B,0))-INDEX(Data_metier!$H:$H,MATCH(F$1,Data_metier!$B:$B,0))> 1, 2, 0))) -> -1 | G10: =IF(INDEX(Data_metier!$H:$H,MATCH($A10,Data_metier!$B:$B,0))-INDEX(Data_metier!$H:$H,MATCH(G$1,Data_metier!$B:$B,0))< 0,-1, IF(AND(INDEX(Data_metier!$H:$H,MATCH($A10,Data_metier!$B:$B,0))-INDEX(Data_metier!$H:$H,MATCH(G$1,Data_metier!$B:$B,0))> 0, INDEX(Data_metier!$H:$H,MATCH($A10,Data_metier!$B:$B,0))-INDEX(Data_metier!$H:$H,MATCH(G$1,Data_metier!$B:$B,0))<=1), 1, IF(INDEX(Data_metier!$H:$H,MATCH($A10,Data_metier!$B:$B,0))-INDEX(Data_metier!$H:$H,MATCH(G$1,Data_metier!$B:$B,0))> 1, 2, 0))) -> -1 | H10: =IF(INDEX(Data_metier!$H:$H,MATCH($A10,Data_metier!$B:$B,0))-INDEX(Data_metier!$H:$H,MATCH(H$1,Data_metier!$B:$B,0))< 0,-1, IF(AND(INDEX(Data_metier!$H:$H,MATCH($A10,Data_metier!$B:$B,0))-INDEX(Data_metier!$H:$H,MATCH(H$1,Data_metier!$B:$B,0))> 0, INDEX(Data_metier!$H:$H,MATCH($A10,Data_metier!$B:$B,0))-INDEX(Data_metier!$H:$H,MATCH(H$1,Data_metier!$B:$B,0))<=1), 1, IF(INDEX(Data_metier!$H:$H,MATCH($A10,Data_metier!$B:$B,0))-INDEX(Data_metier!$H:$H,MATCH(H$1,Data_metier!$B:$B,0))> 1, 2, 0))) -> -1 | I10: =IF(INDEX(Data_metier!$H:$H,MATCH($A10,Data_metier!$B:$B,0))-INDEX(Data_metier!$H:$H,MATCH(I$1,Data_metier!$B:$B,0))< 0,-1, IF(AND(INDEX(Data_metier!$H:$H,MATCH($A10,Data_metier!$B:$B,0))-INDEX(Data_metier!$H:$H,MATCH(I$1,Data_metier!$B:$B,0))> 0, INDEX(Data_metier!$H:$H,MATCH($A10,Data_metier!$B:$B,0))-INDEX(Data_metier!$H:$H,MATCH(I$1,Data_metier!$B:$B,0))<=1), 1, IF(INDEX(Data_metier!$H:$H,MATCH($A10,Data_metier!$B:$B,0))-INDEX(Data_metier!$H:$H,MATCH(I$1,Data_metier!$B:$B,0))> 1, 2, 0))) -> 2 | ... AD10: =IF(INDEX(Data_metier!$H:$H,MATCH($A10,Data_metier!$B:$B,0))-INDEX(Data_metier!$H:$H,MATCH(AD$1,Data_metier!$B:$B,0))< 0,-1, IF(AND(INDEX(Data_metier!$H:$H,MATCH($A10,Data_metier!$B:$B,0))-INDEX(Data_metier!$H:$H,MATCH(AD$1,Data_metier!$B:$B,0))> 0, INDEX(Data_metier!$H:$H,MATCH($A10,Data_metier!$B:$B,0))-INDEX(Data_metier!$H:$H,MATCH(AD$1,Data_metier!$B:$B,0))<=1), 1, IF(INDEX(Data_metier!$H:$H,MATCH($A10,Data_metier!$B:$B,0))-INDEX(Data_metier!$H:$H,MATCH(AD$1,Data_metier!$B:$B,0))> 1, 2, 0))) -> 1
A11: Responsable de production de produits alimentaires (fabrication / conditionnement) | B11: =IF(INDEX(Data_metier!$H:$H,MATCH($A11,Data_metier!$B:$B,0))-INDEX(Data_metier!$H:$H,MATCH(B$1,Data_metier!$B:$B,0))< 0,-1, IF(AND(INDEX(Data_metier!$H:$H,MATCH($A11,Data_metier!$B:$B,0))-INDEX(Data_metier!$H:$H,MATCH(B$1,Data_metier!$B:$B,0))> 0, INDEX(Data_metier!$H:$H,MATCH($A11,Data_metier!$B:$B,0))-INDEX(Data_metier!$H:$H,MATCH(B$1,Data_metier!$B:$B,0))<=1), 1, IF(INDEX(Data_metier!$H:$H,MATCH($A11,Data_metier!$B:$B,0))-INDEX(Data_metier!$H:$H,MATCH(B$1,Data_metier!$B:$B,0))> 1, 2, 0))) -> 2 | C11: =IF(INDEX(Data_metier!$H:$H,MATCH($A11,Data_metier!$B:$B,0))-INDEX(Data_metier!$H:$H,MATCH(C$1,Data_metier!$B:$B,0))< 0,-1, IF(AND(INDEX(Data_metier!$H:$H,MATCH($A11,Data_metier!$B:$B,0))-INDEX(Data_metier!$H:$H,MATCH(C$1,Data_metier!$B:$B,0))> 0, INDEX(Data_metier!$H:$H,MATCH($A11,Data_metier!$B:$B,0))-INDEX(Data_metier!$H:$H,MATCH(C$1,Data_metier!$B:$B,0))<=1), 1, IF(INDEX(Data_metier!$H:$H,MATCH($A11,Data_metier!$B:$B,0))-INDEX(Data_metier!$H:$H,MATCH(C$1,Data_metier!$B:$B,0))> 1, 2, 0))) -> 2 | D11: =IF(INDEX(Data_metier!$H:$H,MATCH($A11,Data_metier!$B:$B,0))-INDEX(Data_metier!$H:$H,MATCH(D$1,Data_metier!$B:$B,0))< 0,-1, IF(AND(INDEX(Data_metier!$H:$H,MATCH($A11,Data_metier!$B:$B,0))-INDEX(Data_metier!$H:$H,MATCH(D$1,Data_metier!$B:$B,0))> 0, INDEX(Data_metier!$H:$H,MATCH($A11,Data_metier!$B:$B,0))-INDEX(Data_metier!$H:$H,MATCH(D$1,Data_metier!$B:$B,0))<=1), 1, IF(INDEX(Data_metier!$H:$H,MATCH($A11,Data_metier!$B:$B,0))-INDEX(Data_metier!$H:$H,MATCH(D$1,Data_metier!$B:$B,0))> 1, 2, 0))) -> 2 | E11: =IF(INDEX(Data_metier!$H:$H,MATCH($A11,Data_metier!$B:$B,0))-INDEX(Data_metier!$H:$H,MATCH(E$1,Data_metier!$B:$B,0))< 0,-1, IF(AND(INDEX(Data_metier!$H:$H,MATCH($A11,Data_metier!$B:$B,0))-INDEX(Data_metier!$H:$H,MATCH(E$1,Data_metier!$B:$B,0))> 0, INDEX(Data_metier!$H:$H,MATCH($A11,Data_metier!$B:$B,0))-INDEX(Data_metier!$H:$H,MATCH(E$1,Data_metier!$B:$B,0))<=1), 1, IF(INDEX(Data_metier!$H:$H,MATCH($A11,Data_metier!$B:$B,0))-INDEX(Data_metier!$H:$H,MATCH(E$1,Data_metier!$B:$B,0))> 1, 2, 0))) -> 2 | F11: =IF(INDEX(Data_metier!$H:$H,MATCH($A11,Data_metier!$B:$B,0))-INDEX(Data_metier!$H:$H,MATCH(F$1,Data_metier!$B:$B,0))< 0,-1, IF(AND(INDEX(Data_metier!$H:$H,MATCH($A11,Data_metier!$B:$B,0))-INDEX(Data_metier!$H:$H,MATCH(F$1,Data_metier!$B:$B,0))> 0, INDEX(Data_metier!$H:$H,MATCH($A11,Data_metier!$B:$B,0))-INDEX(Data_metier!$H:$H,MATCH(F$1,Data_metier!$B:$B,0))<=1), 1, IF(INDEX(Data_metier!$H:$H,MATCH($A11,Data_metier!$B:$B,0))-INDEX(Data_metier!$H:$H,MATCH(F$1,Data_metier!$B:$B,0))> 1, 2, 0))) -> 1 | G11: =IF(INDEX(Data_metier!$H:$H,MATCH($A11,Data_metier!$B:$B,0))-INDEX(Data_metier!$H:$H,MATCH(G$1,Data_metier!$B:$B,0))< 0,-1, IF(AND(INDEX(Data_metier!$H:$H,MATCH($A11,Data_metier!$B:$B,0))-INDEX(Data_metier!$H:$H,MATCH(G$1,Data_metier!$B:$B,0))> 0, INDEX(Data_metier!$H:$H,MATCH($A11,Data_metier!$B:$B,0))-INDEX(Data_metier!$H:$H,MATCH(G$1,Data_metier!$B:$B,0))<=1), 1, IF(INDEX(Data_metier!$H:$H,MATCH($A11,Data_metier!$B:$B,0))-INDEX(Data_metier!$H:$H,MATCH(G$1,Data_metier!$B:$B,0))> 1, 2, 0))) -> 1 | H11: =IF(INDEX(Data_metier!$H:$H,MATCH($A11,Data_metier!$B:$B,0))-INDEX(Data_metier!$H:$H,MATCH(H$1,Data_metier!$B:$B,0))< 0,-1, IF(AND(INDEX(Data_metier!$H:$H,MATCH($A11,Data_metier!$B:$B,0))-INDEX(Data_metier!$H:$H,MATCH(H$1,Data_metier!$B:$B,0))> 0, INDEX(Data_metier!$H:$H,MATCH($A11,Data_metier!$B:$B,0))-INDEX(Data_metier!$H:$H,MATCH(H$1,Data_metier!$B:$B,0))<=1), 1, IF(INDEX(Data_metier!$H:$H,MATCH($A11,Data_metier!$B:$B,0))-INDEX(Data_metier!$H:$H,MATCH(H$1,Data_metier!$B:$B,0))> 1, 2, 0))) -> 1 | I11: =IF(INDEX(Data_metier!$H:$H,MATCH($A11,Data_metier!$B:$B,0))-INDEX(Data_metier!$H:$H,MATCH(I$1,Data_metier!$B:$B,0))< 0,-1, IF(AND(INDEX(Data_metier!$H:$H,MATCH($A11,Data_metier!$B:$B,0))-INDEX(Data_metier!$H:$H,MATCH(I$1,Data_metier!$B:$B,0))> 0, INDEX(Data_metier!$H:$H,MATCH($A11,Data_metier!$B:$B,0))-INDEX(Data_metier!$H:$H,MATCH(I$1,Data_metier!$B:$B,0))<=1), 1, IF(INDEX(Data_metier!$H:$H,MATCH($A11,Data_metier!$B:$B,0))-INDEX(Data_metier!$H:$H,MATCH(I$1,Data_metier!$B:$B,0))> 1, 2, 0))) -> 2 | ... AD11: =IF(INDEX(Data_metier!$H:$H,MATCH($A11,Data_metier!$B:$B,0))-INDEX(Data_metier!$H:$H,MATCH(AD$1,Data_metier!$B:$B,0))< 0,-1, IF(AND(INDEX(Data_metier!$H:$H,MATCH($A11,Data_metier!$B:$B,0))-INDEX(Data_metier!$H:$H,MATCH(AD$1,Data_metier!$B:$B,0))> 0, INDEX(Data_metier!$H:$H,MATCH($A11,Data_metier!$B:$B,0))-INDEX(Data_metier!$H:$H,MATCH(AD$1,Data_metier!$B:$B,0))<=1), 1, IF(INDEX(Data_metier!$H:$H,MATCH($A11,Data_metier!$B:$B,0))-INDEX(Data_metier!$H:$H,MATCH(AD$1,Data_metier!$B:$B,0))> 1, 2, 0))) -> 2
A12: Chauffeur(se) livreur(se) | B12: =IF(INDEX(Data_metier!$H:$H,MATCH($A12,Data_metier!$B:$B,0))-INDEX(Data_metier!$H:$H,MATCH(B$1,Data_metier!$B:$B,0))< 0,-1, IF(AND(INDEX(Data_metier!$H:$H,MATCH($A12,Data_metier!$B:$B,0))-INDEX(Data_metier!$H:$H,MATCH(B$1,Data_metier!$B:$B,0))> 0, INDEX(Data_metier!$H:$H,MATCH($A12,Data_metier!$B:$B,0))-INDEX(Data_metier!$H:$H,MATCH(B$1,Data_metier!$B:$B,0))<=1), 1, IF(INDEX(Data_metier!$H:$H,MATCH($A12,Data_metier!$B:$B,0))-INDEX(Data_metier!$H:$H,MATCH(B$1,Data_metier!$B:$B,0))> 1, 2, 0))) -> -1 | C12: =IF(INDEX(Data_metier!$H:$H,MATCH($A12,Data_metier!$B:$B,0))-INDEX(Data_metier!$H:$H,MATCH(C$1,Data_metier!$B:$B,0))< 0,-1, IF(AND(INDEX(Data_metier!$H:$H,MATCH($A12,Data_metier!$B:$B,0))-INDEX(Data_metier!$H:$H,MATCH(C$1,Data_metier!$B:$B,0))> 0, INDEX(Data_metier!$H:$H,MATCH($A12,Data_metier!$B:$B,0))-INDEX(Data_metier!$H:$H,MATCH(C$1,Data_metier!$B:$B,0))<=1), 1, IF(INDEX(Data_metier!$H:$H,MATCH($A12,Data_metier!$B:$B,0))-INDEX(Data_metier!$H:$H,MATCH(C$1,Data_metier!$B:$B,0))> 1, 2, 0))) -> -1 | D12: =IF(INDEX(Data_metier!$H:$H,MATCH($A12,Data_metier!$B:$B,0))-INDEX(Data_metier!$H:$H,MATCH(D$1,Data_metier!$B:$B,0))< 0,-1, IF(AND(INDEX(Data_metier!$H:$H,MATCH($A12,Data_metier!$B:$B,0))-INDEX(Data_metier!$H:$H,MATCH(D$1,Data_metier!$B:$B,0))> 0, INDEX(Data_metier!$H:$H,MATCH($A12,Data_metier!$B:$B,0))-INDEX(Data_metier!$H:$H,MATCH(D$1,Data_metier!$B:$B,0))<=1), 1, IF(INDEX(Data_metier!$H:$H,MATCH($A12,Data_metier!$B:$B,0))-INDEX(Data_metier!$H:$H,MATCH(D$1,Data_metier!$B:$B,0))> 1, 2, 0))) -> 0 | E12: =IF(INDEX(Data_metier!$H:$H,MATCH($A12,Data_metier!$B:$B,0))-INDEX(Data_metier!$H:$H,MATCH(E$1,Data_metier!$B:$B,0))< 0,-1, IF(AND(INDEX(Data_metier!$H:$H,MATCH($A12,Data_metier!$B:$B,0))-INDEX(Data_metier!$H:$H,MATCH(E$1,Data_metier!$B:$B,0))> 0, INDEX(Data_metier!$H:$H,MATCH($A12,Data_metier!$B:$B,0))-INDEX(Data_metier!$H:$H,MATCH(E$1,Data_metier!$B:$B,0))<=1), 1, IF(INDEX(Data_metier!$H:$H,MATCH($A12,Data_metier!$B:$B,0))-INDEX(Data_metier!$H:$H,MATCH(E$1,Data_metier!$B:$B,0))> 1, 2, 0))) -> -1 | F12: =IF(INDEX(Data_metier!$H:$H,MATCH($A12,Data_metier!$B:$B,0))-INDEX(Data_metier!$H:$H,MATCH(F$1,Data_metier!$B:$B,0))< 0,-1, IF(AND(INDEX(Data_metier!$H:$H,MATCH($A12,Data_metier!$B:$B,0))-INDEX(Data_metier!$H:$H,MATCH(F$1,Data_metier!$B:$B,0))> 0, INDEX(Data_metier!$H:$H,MATCH($A12,Data_metier!$B:$B,0))-INDEX(Data_metier!$H:$H,MATCH(F$1,Data_metier!$B:$B,0))<=1), 1, IF(INDEX(Data_metier!$H:$H,MATCH($A12,Data_metier!$B:$B,0))-INDEX(Data_metier!$H:$H,MATCH(F$1,Data_metier!$B:$B,0))> 1, 2, 0))) -> -1 | G12: =IF(INDEX(Data_metier!$H:$H,MATCH($A12,Data_metier!$B:$B,0))-INDEX(Data_metier!$H:$H,MATCH(G$1,Data_metier!$B:$B,0))< 0,-1, IF(AND(INDEX(Data_metier!$H:$H,MATCH($A12,Data_metier!$B:$B,0))-INDEX(Data_metier!$H:$H,MATCH(G$1,Data_metier!$B:$B,0))> 0, INDEX(Data_metier!$H:$H,MATCH($A12,Data_metier!$B:$B,0))-INDEX(Data_metier!$H:$H,MATCH(G$1,Data_metier!$B:$B,0))<=1), 1, IF(INDEX(Data_metier!$H:$H,MATCH($A12,Data_metier!$B:$B,0))-INDEX(Data_metier!$H:$H,MATCH(G$1,Data_metier!$B:$B,0))> 1, 2, 0))) -> -1 | H12: =IF(INDEX(Data_metier!$H:$H,MATCH($A12,Data_metier!$B:$B,0))-INDEX(Data_metier!$H:$H,MATCH(H$1,Data_metier!$B:$B,0))< 0,-1, IF(AND(INDEX(Data_metier!$H:$H,MATCH($A12,Data_metier!$B:$B,0))-INDEX(Data_metier!$H:$H,MATCH(H$1,Data_metier!$B:$B,0))> 0, INDEX(Data_metier!$H:$H,MATCH($A12,Data_metier!$B:$B,0))-INDEX(Data_metier!$H:$H,MATCH(H$1,Data_metier!$B:$B,0))<=1), 1, IF(INDEX(Data_metier!$H:$H,MATCH($A12,Data_metier!$B:$B,0))-INDEX(Data_metier!$H:$H,MATCH(H$1,Data_metier!$B:$B,0))> 1, 2, 0))) -> -1 | I12: =IF(INDEX(Data_metier!$H:$H,MATCH($A12,Data_metier!$B:$B,0))-INDEX(Data_metier!$H:$H,MATCH(I$1,Data_metier!$B:$B,0))< 0,-1, IF(AND(INDEX(Data_metier!$H:$H,MATCH($A12,Data_metier!$B:$B,0))-INDEX(Data_metier!$H:$H,MATCH(I$1,Data_metier!$B:$B,0))> 0, INDEX(Data_metier!$H:$H,MATCH($A12,Data_metier!$B:$B,0))-INDEX(Data_metier!$H:$H,MATCH(I$1,Data_metier!$B:$B,0))<=1), 1, IF(INDEX(Data_metier!$H:$H,MATCH($A12,Data_metier!$B:$B,0))-INDEX(Data_metier!$H:$H,MATCH(I$1,Data_metier!$B:$B,0))> 1, 2, 0))) -> 0 | ... AD12: =IF(INDEX(Data_metier!$H:$H,MATCH($A12,Data_metier!$B:$B,0))-INDEX(Data_metier!$H:$H,MATCH(AD$1,Data_metier!$B:$B,0))< 0,-1, IF(AND(INDEX(Data_metier!$H:$H,MATCH($A12,Data_metier!$B:$B,0))-INDEX(Data_metier!$H:$H,MATCH(AD$1,Data_metier!$B:$B,0))> 0, INDEX(Data_metier!$H:$H,MATCH($A12,Data_metier!$B:$B,0))-INDEX(Data_metier!$H:$H,MATCH(AD$1,Data_metier!$B:$B,0))<=1), 1, IF(INDEX(Data_metier!$H:$H,MATCH($A12,Data_metier!$B:$B,0))-INDEX(Data_metier!$H:$H,MATCH(AD$1,Data_metier!$B:$B,0))> 1, 2, 0))) -> -1
